<?xml version='1.0' ?>
<!-- Note: this is a fork + simplification of
https://github.com/RobotLocomotion/drake/blob/master/automotive/models/prius/prius.sdf
-->
<sdf version="1.6">
  <model name="prius_1">
    <pose>0 0 0 0 0 0</pose>
    <link name="chassis_footprint">
      <pose>0 0 0 0 0 0</pose>
    </link>
    <link name="chassis_floor">
      <pose>0 0 0.378326 0 0 0</pose>
      <inertial>
        <pose>0 0 0 0 0 0</pose>
        <inertia>
          <ixx>63.858358934</ixx>
          <ixy>0</ixy>
          <ixz>0</ixz>
          <iyy>940.662671467</iyy>
          <iyz>0</iyz>
          <izz>1004.304312533</izz>
        </inertia>
      </inertial>
      <visual name="main">
        <pose>0 0 0 0 0 0</pose>
        <geometry>
          <box>
            <size>2.8808 0.75 0.030921</size>
          </box>
        </geometry>
        <material>
          <diffuse>1 1 1 1</diffuse>
        </material>
      </visual>
    </link>
    <link name="body">
      <pose>0 0 0.385184 0 0 0</pose>
      <inertial>
        <pose>0 0 0 0 0 0</pose>
        <mass>54.2794</mass>
        <inertia>
          <ixx>0.0216238</ixx>
          <ixy>0</ixy>
          <ixz>0</ixz>
          <iyy>5.00375</iyy>
          <iyz>0</iyz>
          <izz>5.01672</izz>
        </inertia>
      </inertial>
      <visual name="visual">
        <pose>-2.27 -0.91139 -0.21858 0 0 0</pose>
        <geometry>
          <mesh>
            <uri>prius.dae</uri>
          </mesh>
        </geometry>
        <material>
          <emissive>0 0 0 1</emissive>
        </material>
      </visual>
    </link>
    <link name="left_wheel">
      <pose>1.40948 0.801993 0.3164819999999999855511135
        1.570796326794896557998982 0 0</pose>
      <inertial>
        <mass>14.28</mass>
        <inertia>
          <ixx>0.499912</ixx>
          <ixy>0</ixy>
          <ixz>0</ixz>
          <iyy>0.778439</iyy>
          <iyz>0</iyz>
          <izz>0.499912</izz>
        </inertia>
      </inertial>
      <visual name="wheel">
        <pose>0 0 0 0 0 0</pose>
        <geometry>
          <cylinder>
            <length>0.215</length>
            <radius>0.323342</radius>
          </cylinder>
        </geometry>
        <material>
          <diffuse>0.2 0.2 0.2 1</diffuse>
        </material>
      </visual>
      <collision name="wheel">
        <pose>0 0 0 0 0 0</pose>
        <geometry>
          <cylinder>
            <radius>0.323342</radius>
            <length>0.215</length>
          </cylinder>
        </geometry>
      </collision>
    </link>
    <link name="right_wheel">
      <pose>1.40948 -0.80198 0.3164819999999999855511135
        1.570796326794896557998982 0 0</pose>
      <inertial>
        <mass>14.28</mass>
        <inertia>
          <ixx>0.499912</ixx>
          <ixy>0</ixy>
          <ixz>0</ixz>
          <iyy>0.778439</iyy>
          <iyz>0</iyz>
          <izz>0.499912</izz>
        </inertia>
      </inertial>
      <visual name="wheel">
        <pose>0 0 0 0 0 0</pose>
        <geometry>
          <cylinder>
            <length>0.215</length>
            <radius>0.323342</radius>
          </cylinder>
        </geometry>
        <material>
          <diffuse>0.2 0.2 0.2 1</diffuse>
        </material>
      </visual>
      <collision name="wheel">
        <pose>0 0 0 0 0 0</pose>
        <geometry>
          <cylinder>
            <radius>0.323342</radius>
            <length>0.215</length>
          </cylinder>
        </geometry>
      </collision>
    </link>
    <link name="left_wheel_rear">
      <pose>-1.40948 0.8019899999999999806732376 0.323342
        1.570796326794896557998982 0 0</pose>
      <inertial>
        <mass>14.28</mass>
        <inertia>
          <ixx>0.499912</ixx>
          <ixy>0</ixy>
          <ixz>0</ixz>
          <iyy>0.778439</iyy>
          <iyz>0</iyz>
          <izz>0.499912</izz>
        </inertia>
      </inertial>
      <visual name="wheel">
        <pose>0 0 0 0 0 0</pose>
        <geometry>
          <cylinder>
            <length>0.215</length>
            <radius>0.323342</radius>
          </cylinder>
        </geometry>
        <material>
          <diffuse>0.2 0.2 0.2 1</diffuse>
        </material>
      </visual>
      <collision name="wheel">
        <pose>0 0 0 0 0 0</pose>
        <geometry>
          <cylinder>
            <radius>0.323342</radius>
            <length>0.215</length>
          </cylinder>
        </geometry>
      </collision>
    </link>
    <link name="right_wheel_rear">
      <pose>-1.40948 -0.8019899999999999806732376 0.323342
        1.570796326794896557998982 0 0</pose>
      <inertial>
        <mass>14.28</mass>
        <inertia>
          <ixx>0.499912</ixx>
          <ixy>0</ixy>
          <ixz>0</ixz>
          <iyy>0.778439</iyy>
          <iyz>0</iyz>
          <izz>0.499912</izz>
        </inertia>
      </inertial>
      <visual name="wheel">
        <pose>0 0 0 0 0 0</pose>
        <geometry>
          <cylinder>
            <length>0.215</length>
            <radius>0.323342</radius>
          </cylinder>
        </geometry>
        <material>
          <diffuse>0.2 0.2 0.2 1</diffuse>
        </material>
      </visual>
      <collision name="wheel">
        <pose>0 0 0 0 0 0</pose>
        <geometry>
          <cylinder>
            <radius>0.323342</radius>
            <length>0.215</length>
          </cylinder>
        </geometry>
      </collision>
    </link>
    <joint name="left_wheel_joint" type="revolute">
      <parent>chassis_floor</parent>
      <child>left_wheel</child>
      <pose>0 0 0 0 0 0</pose>
      <axis>
        <xyz>0 1 0</xyz>
        <use_parent_model_frame>1</use_parent_model_frame>
      </axis>
    </joint>
    <joint name="rear_left_wheel_joint" type="revolute">
      <parent>chassis_floor</parent>
      <child>left_wheel_rear</child>
      <pose>0 0 0 0 0 0</pose>
      <axis>
        <xyz>0 1 0</xyz>
        <use_parent_model_frame>1</use_parent_model_frame>
        <limit>
          <effort>0</effort>
        </limit>
      </axis>
    </joint>
    <joint name="rear_right_wheel_joint" type="revolute">
      <parent>chassis_floor</parent>
      <child>right_wheel_rear</child>
      <pose>0 0 0 0 0 0</pose>
      <axis>
        <xyz>0 1 0</xyz>
        <use_parent_model_frame>1</use_parent_model_frame>
        <limit>
          <effort>0</effort>
        </limit>
      </axis>
    </joint>
    <joint name="right_wheel_joint" type="revolute">
      <parent>chassis_floor</parent>
      <child>right_wheel</child>
      <pose>0 0 0 0 0 0</pose>
      <axis>
        <xyz>0 1 0</xyz>
        <use_parent_model_frame>1</use_parent_model_frame>
      </axis>
    </joint>
    <joint name="body_joint" type="fixed">
      <parent>chassis_floor</parent>
      <child>body</child>
      <pose>0 0 0 0 0 0</pose>
    </joint>
    <joint name="chassis_floor_joint" type="fixed">
      <parent>chassis_footprint</parent>
      <child>chassis_floor</child>
      <pose>0 0 0 0 0 0</pose>
    </joint>
  </model>
</sdf>
